Workbook

Sheet Painel
B2: Painel do funil - Fase 1
B3: Tudo aqui se calcula a partir da aba Lista 200. Nao digite nada nesta aba.
B5: BOXES NA LISTA | D5: PRIORIDADE A | F5: JA ABORDADOS | H5: GANHOS | J5: VAGAS RESTANTES
B6: =COUNTA('Lista 200'!$B$2:$B$201) | D6: =COUNTIF('Lista 200'!$M$2:$M$201,"A") | F6: =SUM(C12:C18) | H6: =COUNTIF('Lista 200'!$N$2:$N$201,"Ganho") | J6: =20-COUNTIF('Lista 200'!$N$2:$N$201,"Ganho")
B9: Funil | F9: Taxas que importam
B10: Etapa | C10: Qtd | D10: % da lista | F10: Etapa | H10: Taxa
B11: Nao contatado | C11: =COUNTIF('Lista 200'!$N$2:$N$201,"Nao contatado") | D11: =IFERROR(C11/$B$6,0) | F11: Abordagem -> conversa | H11: =IFERROR((C13+C14+C15+C16+C17)/(C12+C13+C14+C15+C16+C17),0)
B12: Abordado | C12: =COUNTIF('Lista 200'!$N$2:$N$201,"Abordado") | D12: =IFERROR(C12/$B$6,0) | F12: Conversa -> demo feita | H12: =IFERROR((C15+C16+C17)/(C13+C14+C15+C16+C17),0)
B13: Conversando | C13: =COUNTIF('Lista 200'!$N$2:$N$201,"Conversando") | D13: =IFERROR(C13/$B$6,0) | F13: Demo feita -> ganho | H13: =IFERROR(C17/(C15+C16+C17),0)
B14: Demo agendada | C14: =COUNTIF('Lista 200'!$N$2:$N$201,"Demo agendada") | D14: =IFERROR(C14/$B$6,0) | F14: Ganho sobre lista trabalhada | H14: =IFERROR(C17/SUM(C12:C18),0)
B15: Demo feita | C15: =COUNTIF('Lista 200'!$N$2:$N$201,"Demo feita") | D15: =IFERROR(C15/$B$6,0)
B16: Proposta enviada | C16: =COUNTIF('Lista 200'!$N$2:$N$201,"Proposta enviada") | D16: =IFERROR(C16/$B$6,0)
B17: Ganho | C17: =COUNTIF('Lista 200'!$N$2:$N$201,"Ganho") | D17: =IFERROR(C17/$B$6,0) | F17: Ritmo
B18: Perdido | C18: =COUNTIF('Lista 200'!$N$2:$N$201,"Perdido") | D18: =IFERROR(C18/$B$6,0) | F18: Acoes vencidas (data passou e nao fechou) | H18: =SUMPRODUCT(('Lista 200'!$R$2:$R$201<>"")*('Lista 200'!$R$2:$R$201<TODAY())*('Lista 200'!$N$2:$N$201<>"Ganho")*('Lista 200'!$N$2:$N$201<>"Perdido")*('Lista 200'!$N$2:$N$201<>"Descartado"))
B19: Descartado | C19: =COUNTIF('Lista 200'!$N$2:$N$201,"Descartado") | D19: =IFERROR(C19/$B$6,0) | F19: Total de toques registrados | H19: =SUM('Lista 200'!$P$2:$P$201)
B22: Leitura: se Abordagem -> conversa ficar abaixo de ~20%, o problema esta na mensagem de abertura. Se Demo feita -> ganho ficar abaixo de ~30%, o problema esta na oferta ou na qualificacao - nao no volume de abordagens.

Sheet Metodo
B2: Metodo - como preencher e usar a Lista dos 200
B3: Fase 1 do plano de escala | meta: 20 boxes fundadores | ritmo alvo: 10 abordagens por dia
B5: 1. De onde tirar os 200 nomes
B6: Google Maps: buscar crossfit, cross training, box e treino funcional bairro por bairro. Instagram: as mesmas palavras + cidade, e os seguidores dos boxes que voce ja conhece.
B8: 2. O que preencher primeiro
B9: So as colunas amarelas. Score e Prioridade se calculam sozinhos. Nao pare para pesquisar tudo de um box: preencha o que da em 2 minutos e siga - a lista vale pelo volume, nao pela perfeicao de cada linha.
B11: 3. Como ler os sinais de dor
B12: WOD em foto de quadro branco no feed = nao tem sistema de treino. Sem app do aluno = a rotina do aluno vive no WhatsApp. Chama no direct pra saber valores = comercial e cobranca na mao do dono.
B14: 4. Por onde comecar a abordar
B15: So prioridade A. Nao gaste os primeiros dias com B e C: voce ainda esta aprendendo o script, e esse aprendizado fica caro se for gasto no lead errado.
B17: 5. O que fazer todo dia
B18: 10 abordagens novas, responder quem respondeu e mover o status de quem avancou. O Painel conta sozinho.
... B27: Tamanho do box (alunos)
B28: Entre 80 e 250 alunos (alvo) | C28: 30
B29: Entre 40 e 79, ou entre 251 e 400 | C29: 15
B30: Fora da faixa ou em branco | C30: 5
B31: Sistema que usa hoje
B32: Planilha ou caderno | C32: 25
B33: Nenhum sistema | C33: 25
B34: Desconhecido | C34: 10
B35: Concorrente | C35: 5
B36: Sinais de dor
B37: Peso por sinal marcado (ate 3) | C37: 10
B38: Regiao
B39: Grande SP | C39: 15
B40: SP interior | C40: 8
B41: Outro estado | C41: 3
B42: Corte de prioridade
B43: Score minimo para prioridade A | C43: 70
B44: Score minimo para prioridade B | C44: 50
B46: Amarelo = voce edita. Azul claro na Lista 200 = calculado, nao digite por cima.

Sheet Lista 200
A1: # | B1: Box | C1: Cidade / bairro | D1: Instagram | E1: WhatsApp | F1: Alunos (est.) | G1: Sistema hoje | H1: WOD no quadro | I1: Sem app aluno | J1: Cobranca manual | K1: Regiao | L1: Score | M1: Prior. | N1: Status | O1: Ultimo toque | P1: Toques | Q1: Proxima acao | R1: Quando | S1: Objecao principal | T1: Notas
A2: =IF($B2="","",ROW()-1) | B2: Endorfina Cross | C2: Guarulhos - SP | D2: @endorfinacross | E2: (11) 9xxxx-xxxx | F2: 180 | G2: Planilha ou caderno | H2: Sim | I2: Sim | J2: Sim | K2: Grande SP | L2: =IF($B2="","",IF($F2="",Metodo!$C$30,IF(AND($F2>=80,$F2<=250),Metodo!$C$28,IF(OR(AND($F2>=40,$F2<=79),AND($F2>=251,$F2<=400)),Metodo!$C$29,Metodo!$C$30)))+IFERROR(INDEX(Metodo!$C$32:$C$35,MATCH($G2,Metodo!$B$32:$B$35,0)),0)+COUNTIF($H2:$J2,"Sim")*Metodo!$C$37+IFERROR(INDEX(Metodo!$C$39:$C$41,MATCH($K2,Metodo!$B$39:$B$41,0)),0)) | M2: =IF($L2="","",IF($L2>=Metodo!$C$43,"A",IF($L2>=Metodo!$C$44,"B","C"))) | N2: Ganho | P2: 6 | Q2: Acompanhar uso semanal | S2: - | T2: Linha real e ja ganha: primeiro box em producao desde 23/05. Serve de modelo de preenchimento - comece a sua lista na linha 3.
A3: =IF($B3="","",ROW()-1) | B3: Arujá Crossfit Guarulhos | C3: Guarulhos - Centro | E3: +55 11 96646-4324 | K3: Grande SP | L3: =IF($B3="","",IF($F3="",Metodo!$C$30,IF(AND($F3>=80,$F3<=250),Metodo!$C$28,IF(OR(AND($F3>=40,$F3<=79),AND($F3>=251,$F3<=400)),Metodo!$C$29,Metodo!$C$30)))+IFERROR(INDEX(Metodo!$C$32:$C$35,MATCH($G3,Metodo!$B$32:$B$35,0)),0)+COUNTIF($H3:$J3,"Sim")*Metodo!$C$37+IFERROR(INDEX(Metodo!$C$39:$C$41,MATCH($K3,Metodo!$B$39:$B$41,0)),0)) | M3: =IF($L3="","",IF($L3>=Metodo!$C$43,"A",IF($L3>=Metodo!$C$44,"B","C"))) | N3: Nao contatado | Q3: Primeiro contato | T3: Tier 1 (varredura TomTom 2026-08-29, PR #185). Qualificacao: sem site. Sem Instagram proprio localizavel via busca - so aparece em agregador (FitFit.Fitness, nota 9,2/10 e 4,4/5). Endereco: Av. Paulo Faccini 691. Abertura generica (sem sinal especifico).
A4: =IF($B4="","",ROW()-1) | B4: CrossFit Forvy | C4: Guarulhos - Centro | D4: @crossfitforvy | E4: +55 11 93394-9736 | K4: Grande SP | L4: =IF($B4="","",IF($F4="",Metodo!$C$30,IF(AND($F4>=80,$F4<=250),Metodo!$C$28,IF(OR(AND($F4>=40,$F4<=79),AND($F4>=251,$F4<=400)),Metodo!$C$29,Metodo!$C$30)))+IFERROR(INDEX(Metodo!$C$32:$C$35,MATCH($G4,Metodo!$B$32:$B$35,0)),0)+COUNTIF($H4:$J4,"Sim")*Metodo!$C$37+IFERROR(INDEX(Metodo!$C$39:$C$41,MATCH($K4,Metodo!$B$39:$B$41,0)),0)) | M4: =IF($L4="","",IF($L4>=Metodo!$C$43,"A",IF($L4>=Metodo!$C$44,"B","C"))) | N4: Nao contatado | Q4: Primeiro contato | T4: Tier 1 (varredura TomTom 2026-08-29, PR #185). Qualificacao: afiliado oficial. Instagram @crossfitforvy, 3 mil seguidores, 511 posts, ativo. Fez Festivus Games em 2026-04.
A5: =IF($B5="","",ROW()-1) | B5: CrossFit MK-1 | C5: Guarulhos - Picanço | D5: @crossfitmk1 | E5: +55 11 98964-7226 | K5: Grande SP | L5: =IF($B5="","",IF($F5="",Metodo!$C$30,IF(AND($F5>=80,$F5<=250),Metodo!$C$28,IF(OR(AND($F5>=40,$F5<=79),AND($F5>=251,$F5<=400)),Metodo!$C$29,Metodo!$C$30)))+IFERROR(INDEX(Metodo!$C$32:$C$35,MATCH($G5,Metodo!$B$32:$B$35,0)),0)+COUNTIF($H5:$J5,"Sim")*Metodo!$C$37+IFERROR(INDEX(Metodo!$C$39:$C$41,MATCH($K5,Metodo!$B$39:$B$41,0)),0)) | M5: =IF($L5="","",IF($L5>=Metodo!$C$43,"A",IF($L5>=Metodo!$C$44,"B","C"))) | N5: Nao contatado | Q5: Primeiro contato | T5: Tier 1 (varredura TomTom 2026-08-29, PR #185). Qualificacao: site proprio. Instagram @crossfitmk1, 11,1 mil seguidores, desde 2012, pioneira em Guarulhos, tem CrossFit Kids. Possivel rede de 2 unidades com a MK1 Vila Galvao (linha 6) - confirmar.
A6: =IF($B6="","",ROW()-1) | B6: CrossFit MK1 Vila Galvão | C6: Guarulhos - Vila Galvão | D6: @crossfitmk1 | E6: +55 11 91223-9182 | K6: Grande SP | L6: =IF($B6="","",IF($F6="",Metodo!$C$30,IF(AND($F6>=80,$F6<=250),Metodo!$C$28,IF(OR(AND($F6>=40,$F6<=79),AND($F6>=251,$F6<=400)),Metodo!$C$29,Metodo!$C$30)))+IFERROR(INDEX(Metodo!$C$32:$C$35,MATCH($G6,Metodo!$B$32:$B$35,0)),0)+COUNTIF($H6:$J6,"Sim")*Metodo!$C$37+IFERROR(INDEX(Metodo!$C$39:$C$41,MATCH($K6,Metodo!$B$39:$B$41,0)),0)) | M6: =IF($L6="","",IF($L6>=Metodo!$C$43,"A",IF($L6>=Metodo!$C$44,"B","C"))) | N6: Nao contatado | Q6: Primeiro contato | T6: Tier 1 (varredura TomTom 2026-08-29, PR #185). Qualificacao: afiliado oficial. Mesma marca/Instagram da MK-1 Picanco (linha 5) - possivel 2a unidade da mesma rede, nao a mesma pessoa necessariamente. Confirmar antes de abordar como lead separado.
A7: =IF($B7="","",ROW()-1) | B7: CrossFit Saurus Bosque Maia | C7: Guarulhos - Vila Rio | D7: @crossfitsaurus | E7: +55 11 98254-0787 | K7: Grande SP | L7: =IF($B7="","",IF($F7="",Metodo!$C$30,IF(AND($F7>=80,$F7<=250),Metodo!$C$28,IF(OR(AND($F7>=40,$F7<=79),AND($F7>=251,$F7<=400)),Metodo!$C$29,Metodo!$C$30)))+IFERROR(INDEX(Metodo!$C$32:$C$35,MATCH($G7,Metodo!$B$32:$B$35,0)),0)+COUNTIF($H7:$J7,"Sim")*Metodo!$C$37+IFERROR(INDEX(Metodo!$C$39:$C$41,MATCH($K7,Metodo!$B$39:$B$41,0)),0)) | M7: =IF($L7="","",IF($L7>=Metodo!$C$43,"A",IF($L7>=Metodo!$C$44,"B","C"))) | N7: Nao contatado | Q7: Primeiro contato | T7: Tier 1 (varredura TomTom 2026-08-29, PR #185). Qualificacao: site proprio. ATENCAO: parece rede com 3+ unidades (Bosque Maia, Vila Guilherme, Freguesia, possivelmente mais - o mesmo telefone aparece tambem no Tier 2 como "CrossFit Saurus" em Vila Guilherme). Regra do script (secao 6) desqualifica rede com mais de 3 unidades na Fase 1 - confirmar com Renan antes de abordar; se confirmado, marcar Descartado.
A8: =IF($B8="","",ROW()-1) | B8: CrossFit Vila Augusta | C8: Guarulhos - Vila Augusta | D8: @crossfitvilaaugusta | E8: +55 11 93022-9182 | K8: Grande SP | L8: =IF($B8="","",IF($F8="",Metodo!$C$30,IF(AND($F8>=80,$F8<=250),Metodo!$C$28,IF(OR(AND($F8>=40,$F8<=79),AND($F8>=251,$F8<=400)),Metodo!$C$29,Metodo!$C$30)))+IFERROR(INDEX(Metodo!$C$32:$C$35,MATCH($G8,Metodo!$B$32:$B$35,0)),0)+COUNTIF($H8:$J8,"Sim")*Metodo!$C$37+IFERROR(INDEX(Metodo!$C$39:$C$41,MATCH($K8,Metodo!$B$39:$B$41,0)),0)) | M8: =IF($L8="","",IF($L8>=Metodo!$C$43,"A",IF($L8>=Metodo!$C$44,"B","C"))) | N8: Nao contatado | Q8: Primeiro contato | T8: Tier 1 (varredura TomTom 2026-08-29, PR #185). Qualificacao: afiliado oficial. Instagram @crossfitvilaaugusta, 1,2 mil seguidores. Comunidade bem ativa: aulao de dia dos pais, churrasco do box, musica ao vivo - perfil familiar/comunitario forte.
A9: =IF($B9="","",ROW()-1) | B9: Crossfit GRU | C9: Guarulhos - Vila Augusta | D9: @cf_gru | E9: +55 11 97246-7271 | K9: Grande SP | L9: =IF($B9="","",IF($F9="",Metodo!$C$30,IF(AND($F9>=80,$F9<=250),Metodo!$C$28,IF(OR(AND($F9>=40,$F9<=79),AND($F9>=251,$F9<=400)),Metodo!$C$29,Metodo!$C$30)))+IFERROR(INDEX(Metodo!$C$32:$C$35,MATCH($G9,Metodo!$B$32:$B$35,0)),0)+COUNTIF($H9:$J9,"Sim")*Metodo!$C$37+IFERROR(INDEX(Metodo!$C$39:$C$41,MATCH($K9,Metodo!$B$39:$B$41,0)),0)) | M9: =IF($L9="","",IF($L9>=Metodo!$C$43,"A",IF($L9>=Metodo!$C$44,"B","C"))) | N9: Nao contatado | Q9: Primeiro contato | T9: Tier 1 (varredura TomTom 2026-08-29, PR #185). Qualificacao: site proprio. Instagram @cf_gru, 6,1 mil seguidores, 8+ anos de historia. Posta o WOD do dia no feed regularmente (sinal direto da Variante A do script). Tem e-mail proprio (contato@crossfitgru.com).
A10: =IF($B10="","",ROW()-1) | B10: CrossFit Barueri | C10: Barueri - Alphaville | E10: +55 11 97503-7921 | K10: Grande SP | L10: =IF($B10="","",IF($F10="",Metodo!$C$30,IF(AND($F10>=80,$F10<=250),Metodo!$C$28,IF(OR(AND($F10>=40,$F10<=79),AND($F10>=251,$F10<=400)),Metodo!$C$29,Metodo!$C$30)))+IFERROR(INDEX(Metodo!$C$32:$C$35,MATCH($G10,Metodo!$B$32:$B$35,0)),0)+COUNTIF($H10:$J10,"Sim")*Metodo!$C$37+IFERROR(INDEX(Metodo!$C$39:$C$41,MATCH($K10,Metodo!$B$39:$B$41,0)),0)) | M10: =IF($L10="","",IF($L10>=Metodo!$C$43,"A",IF($L10>=Metodo!$C$44,"B","C"))) | N10: Nao contatado | Q10: Primeiro contato | T10: Tier 2 (varredura TomTom 2026-08-29, PR #185). Qualificacao: afiliado oficial.
A11: =IF($B11="","",ROW()-1) | B11: CrossFit Rudge Ramos | C11: São Bernardo do Campo - Anchieta | K11: Grande SP | L11: =IF($B11="","",IF($F11="",Metodo!$C$30,IF(AND($F11>=80,$F11<=250),Metodo!$C$28,IF(OR(AND($F11>=40,$F11<=79),AND($F11>=251,$F11<=400)),Metodo!$C$29,Metodo!$C$30)))+IFERROR(INDEX(Metodo!$C$32:$C$35,MATCH($G11,Metodo!$B$32:$B$35,0)),0)+COUNTIF($H11:$J11,"Sim")*Metodo!$C$37+IFERROR(INDEX(Metodo!$C$39:$C$41,MATCH($K11,Metodo!$B$39:$B$41,0)),0)) | M11: =IF($L11="","",IF($L11>=Metodo!$C$43,"A",IF($L11>=Metodo!$C$44,"B","C"))) | N11: Nao contatado | Q11: Achar contato | T11: Tier 2 (varredura TomTom 2026-08-29, PR #185). Qualificacao: afiliado oficial.
A12: =IF($B12="","",ROW()-1) | B12: Soren CrossFit | C12: São Bernardo do Campo - Anchieta | E12: +55 11 95941-3662 | K12: Grande SP | L12: =IF($B12="","",IF($F12="",Metodo!$C$30,IF(AND($F12>=80,$F12<=250),Metodo!$C$28,IF(OR(AND($F12>=40,$F12<=79),AND($F12>=251,$F12<=400)),Metodo!$C$29,Metodo!$C$30)))+IFERROR(INDEX(Metodo!$C$32:$C$35,MATCH($G12,Metodo!$B$32:$B$35,0)),0)+COUNTIF($H12:$J12,"Sim")*Metodo!$C$37+IFERROR(INDEX(Metodo!$C$39:$C$41,MATCH($K12,Metodo!$B$39:$B$41,0)),0)) | M12: =IF($L12="","",IF($L12>=Metodo!$C$43,"A",IF($L12>=Metodo!$C$44,"B","C"))) | N12: Nao contatado | Q12: Primeiro contato | T12: Tier 2 (varredura TomTom 2026-08-29, PR #185). Qualificacao: afiliado oficial.
A13: =IF($B13="","",ROW()-1) | B13: B4thor CrossFit | C13: São Paulo - Campo Belo | E13: +55 11 98244-0880 | K13: Grande SP | L13: =IF($B13="","",IF($F13="",Metodo!$C$30,IF(AND($F13>=80,$F13<=250),Metodo!$C$28,IF(OR(AND($F13>=40,$F13<=79),AND($F13>=251,$F13<=400)),Metodo!$C$29,Metodo!$C$30)))+IFERROR(INDEX(Metodo!$C$32:$C$35,MATCH($G13,Metodo!$B$32:$B$35,0)),0)+COUNTIF($H13:$J13,"Sim")*Metodo!$C$37+IFERROR(INDEX(Metodo!$C$39:$C$41,MATCH($K13,Metodo!$B$39:$B$41,0)),0)) | M13: =IF($L13="","",IF($L13>=Metodo!$C$43,"A",IF($L13>=Metodo!$C$44,"B","C"))) | N13: Nao contatado | Q13: Primeiro contato | T13: Tier 2 (varredura TomTom 2026-08-29, PR #185). Qualificacao: afiliado oficial.
A14: =IF($B14="","",ROW()-1) | B14: CrossFit | C14: São Paulo - Pinheiros | E14: +55 11 97358-5345 | K14: Grande SP | L14: =IF($B14="","",IF($F14="",Metodo!$C$30,IF(AND($F14>=80,$F14<=250),Metodo!$C$28,IF(OR(AND($F14>=40,$F14<=79),AND($F14>=251,$F14<=400)),Metodo!$C$29,Metodo!$C$30)))+IFERROR(INDEX(Metodo!$C$32:$C$35,MATCH($G14,Metodo!$B$32:$B$35,0)),0)+COUNTIF($H14:$J14,"Sim")*Metodo!$C$37+IFERROR(INDEX(Metodo!$C$39:$C$41,MATCH($K14,Metodo!$B$39:$B$41,0)),0)) | M14: =IF($L14="","",IF($L14>=Metodo!$C$43,"A",IF($L14>=Metodo!$C$44,"B","C"))) | N14: Nao contatado | Q14: Primeiro contato | T14: Tier 2 (varredura TomTom 2026-08-29, PR #185). Qualificacao: afiliado oficial.
A15: =IF($B15="","",ROW()-1) | B15: CrossFit Azteca | C15: São Paulo - Santo Amaro | E15: +55 11 97205-9595 | K15: Grande SP | L15: =IF($B15="","",IF($F15="",Metodo!$C$30,IF(AND($F15>=80,$F15<=250),Metodo!$C$28,IF(OR(AND($F15>=40,$F15<=79),AND($F15>=251,$F15<=400)),Metodo!$C$29,Metodo!$C$30)))+IFERROR(INDEX(Metodo!$C$32:$C$35,MATCH($G15,Metodo!$B$32:$B$35,0)),0)+COUNTIF($H15:$J15,"Sim")*Metodo!$C$37+IFERROR(INDEX(Metodo!$C$39:$C$41,MATCH($K15,Metodo!$B$39:$B$41,0)),0)) | M15: =IF($L15="","",IF($L15>=Metodo!$C$43,"A",IF($L15>=Metodo!$C$44,"B","C"))) | N15: Nao contatado | Q15: Primeiro contato | T15: Tier 2 (varredura TomTom 2026-08-29, PR #185). Qualificacao: afiliado oficial.
A16: =IF($B16="","",ROW()-1) | B16: CrossFit Batalha | C16: São Paulo - Jacana | D16: @crossfitbatalha | E16: +55 11 94037-4949 | K16: Grande SP | L16: =IF($B16="","",IF($F16="",Metodo!$C$30,IF(AND($F16>=80,$F16<=250),Metodo!$C$28,IF(OR(AND($F16>=40,$F16<=79),AND($F16>=251,$F16<=400)),Metodo!$C$29,Metodo!$C$30)))+IFERROR(INDEX(Metodo!$C$32:$C$35,MATCH($G16,Metodo!$B$32:$B$35,0)),0)+COUNTIF($H16:$J16,"Sim")*Metodo!$C$37+IFERROR(INDEX(Metodo!$C$39:$C$41,MATCH($K16,Metodo!$B$39:$B$41,0)),0)) | M16: =IF($L16="","",IF($L16>=Metodo!$C$43,"A",IF($L16>=Metodo!$C$44,"B","C"))) | N16: Nao contatado | Q16: Primeiro contato | T16: Tier 2 (varredura TomTom 2026-08-29, PR #185). Qualificacao: afiliado oficial. Instagram @crossfitbatalha, 3,7 mil seguidores, Jacana/zona norte. Posiciona "CrossFit e para TODOS" e agenda aula experimental direto pelo Instagram - fluxo de agendamento manual.
A17: =IF($B17="","",ROW()-1) | B17: CrossFit Beco | C17: São Paulo - Vila Leopoldina | E17: +55 11 95240-4007 | K17: Grande SP | L17: =IF($B17="","",IF($F17="",Metodo!$C$30,IF(AND($F17>=80,$F17<=250),Metodo!$C$28,IF(OR(AND($F17>=40,$F17<=79),AND($F17>=251,$F17<=400)),Metodo!$C$29,Metodo!$C$30)))+IFERROR(INDEX(Metodo!$C$32:$C$35,MATCH($G17,Metodo!$B$32:$B$35,0)),0)+COUNTIF($H17:$J17,"Sim")*Metodo!$C$37+IFERROR(INDEX(Metodo!$C$39:$C$41,MATCH($K17,Metodo!$B$39:$B$41,0)),0)) | M17: =IF($L17="","",IF($L17>=Metodo!$C$43,"A",IF($L17>=Metodo!$C$44,"B","C"))) | N17: Nao contatado | Q17: Primeiro contato | T17: Tier 2 (varredura TomTom 2026-08-29, PR #185). Qualificacao: afiliado oficial.
A18: =IF($B18="","",ROW()-1) | B18: CrossFit Betta | C18: São Paulo - Mandaqui | D18: @crossfitbetta | E18: +55 11 2281-9110 | K18: Grande SP | L18: =IF($B18="","",IF($F18="",Metodo!$C$30,IF(AND($F18>=80,$F18<=250),Metodo!$C$28,IF(OR(AND($F18>=40,$F18<=79),AND($F18>=251,$F18<=400)),Metodo!$C$29,Metodo!$C$30)))+IFERROR(INDEX(Metodo!$C$32:$C$35,MATCH($G18,Metodo!$B$32:$B$35,0)),0)+COUNTIF($H18:$J18,"Sim")*Metodo!$C$37+IFERROR(INDEX(Metodo!$C$39:$C$41,MATCH($K18,Metodo!$B$39:$B$41,0)),0)) | M18: =IF($L18="","",IF($L18>=Metodo!$C$43,"A",IF($L18>=Metodo!$C$44,"B","C"))) | N18: Nao contatado | Q18: Primeiro contato | T18: Tier 2 (varredura TomTom 2026-08-29, PR #185). Qualificacao: afiliado oficial. Instagram @crossfitbetta, quase 4 mil seguidores, Mandaqui. Posicionamento de bem-estar ("saude fisica e mental", "mais que uma academia").
A19: =IF($B19="","",ROW()-1) | B19: CrossFit Bronx | C19: São Paulo - Itaim Bibi | E19: +55 11 99292-6136 | K19: Grande SP | L19: =IF($B19="","",IF($F19="",Metodo!$C$30,IF(AND($F19>=80,$F19<=250),Metodo!$C$28,IF(OR(AND($F19>=40,$F19<=79),AND($F19>=251,$F19<=400)),Metodo!$C$29,Metodo!$C$30)))+IFERROR(INDEX(Metodo!$C$32:$C$35,MATCH($G19,Metodo!$B$32:$B$35,0)),0)+COUNTIF($H19:$J19,"Sim")*Metodo!$C$37+IFERROR(INDEX(Metodo!$C$39:$C$41,MATCH($K19,Metodo!$B$39:$B$41,0)),0)) | M19: =IF($L19="","",IF($L19>=Metodo!$C$43,"A",IF($L19>=Metodo!$C$44,"B","C"))) | N19: Nao contatado | Q19: Primeiro contato | T19: Tier 2 (varredura TomTom 2026-08-29, PR #185). Qualificacao: afiliado oficial.
A20: =IF($B20="","",ROW()-1) | B20: CrossFit Campo Bacharel | C20: São Paulo - Campo Belo | E20: +55 11 2397-0779 | K20: Grande SP | L20: =IF($B20="","",IF($F20="",Metodo!$C$30,IF(AND($F20>=80,$F20<=250),Metodo!$C$28,IF(OR(AND($F20>=40,$F20<=79),AND($F20>=251,$F20<=400)),Metodo!$C$29,Metodo!$C$30)))+IFERROR(INDEX(Metodo!$C$32:$C$35,MATCH($G20,Metodo!$B$32:$B$35,0)),0)+COUNTIF($H20:$J20,"Sim")*Metodo!$C$37+IFERROR(INDEX(Metodo!$C$39:$C$41,MATCH($K20,Metodo!$B$39:$B$41,0)),0)) | M20: =IF($L20="","",IF($L20>=Metodo!$C$43,"A",IF($L20>=Metodo!$C$44,"B","C"))) | N20: Nao contatado | Q20: Primeiro contato | T20: Tier 2 (varredura TomTom 2026-08-29, PR #185). Qualificacao: afiliado oficial.
A21: =IF($B21="","",ROW()-1) | B21: CrossFit City Wolves | C21: São Paulo - Saúde | E21: +55 11 99358-0631 | K21: Grande SP | L21: =IF($B21="","",IF($F21="",Metodo!$C$30,IF(AND($F21>=80,$F21<=250),Metodo!$C$28,IF(OR(AND($F21>=40,$F21<=79),AND($F21>=251,$F21<=400)),Metodo!$C$29,Metodo!$C$30)))+IFERROR(INDEX(Metodo!$C$32:$C$35,MATCH($G21,Metodo!$B$32:$B$35,0)),0)+COUNTIF($H21:$J21,"Sim")*Metodo!$C$37+IFERROR(INDEX(Metodo!$C$39:$C$41,MATCH($K21,Metodo!$B$39:$B$41,0)),0)) | M21: =IF($L21="","",IF($L21>=Metodo!$C$43,"A",IF($L21>=Metodo!$C$44,"B","C"))) | N21: Nao contatado | Q21: Primeiro contato | T21: Tier 2 (varredura TomTom 2026-08-29, PR #185). Qualificacao: afiliado oficial.
A22: =IF($B22="","",ROW()-1) | B22: CrossFit Conceição | C22: São Paulo - Jabaquara | E22: +55 11 5017-7283 | K22: Grande SP | L22: =IF($B22="","",IF($F22="",Metodo!$C$30,IF(AND($F22>=80,$F22<=250),Metodo!$C$28,IF(OR(AND($F22>=40,$F22<=79),AND($F22>=251,$F22<=400)),Metodo!$C$29,Metodo!$C$30)))+IFERROR(INDEX(Metodo!$C$32:$C$35,MATCH($G22,Metodo!$B$32:$B$35,0)),0)+COUNTIF($H22:$J22,"Sim")*Metodo!$C$37+IFERROR(INDEX(Metodo!$C$39:$C$41,MATCH($K22,Metodo!$B$39:$B$41,0)),0)) | M22: =IF($L22="","",IF($L22>=Metodo!$C$43,"A",IF($L22>=Metodo!$C$44,"B","C"))) | N22: Nao contatado | Q22: Primeiro contato | T22: Tier 2 (varredura TomTom 2026-08-29, PR #185). Qualificacao: afiliado oficial.
A23: =IF($B23="","",ROW()-1) | B23: CrossFit Fire Hawks | C23: São Paulo - Vila Mariana | E23: +55 11 96609-2246 | K23: Grande SP | L23: =IF($B23="","",IF($F23="",Metodo!$C$30,IF(AND($F23>=80,$F23<=250),Metodo!$C$28,IF(OR(AND($F23>=40,$F23<=79),AND($F23>=251,$F23<=400)),Metodo!$C$29,Metodo!$C$30)))+IFERROR(INDEX(Metodo!$C$32:$C$35,MATCH($G23,Metodo!$B$32:$B$35,0)),0)+COUNTIF($H23:$J23,"Sim")*Metodo!$C$37+IFERROR(INDEX(Metodo!$C$39:$C$41,MATCH($K23,Metodo!$B$39:$B$41,0)),0)) | M23: =IF($L23="","",IF($L23>=Metodo!$C$43,"A",IF($L23>=Metodo!$C$44,"B","C"))) | N23: Nao contatado | Q23: Primeiro contato | T23: Tier 2 (varredura TomTom 2026-08-29, PR #185). Qualificacao: afiliado oficial.
A24: =IF($B24="","",ROW()-1) | B24: CrossFit Four Heads | C24: São Paulo - Saúde | E24: +55 11 99170-7922 | K24: Grande SP | L24: =IF($B24="","",IF($F24="",Metodo!$C$30,IF(AND($F24>=80,$F24<=250),Metodo!$C$28,IF(OR(AND($F24>=40,$F24<=79),AND($F24>=251,$F24<=400)),Metodo!$C$29,Metodo!$C$30)))+IFERROR(INDEX(Metodo!$C$32:$C$35,MATCH($G24,Metodo!$B$32:$B$35,0)),0)+COUNTIF($H24:$J24,"Sim")*Metodo!$C$37+IFERROR(INDEX(Metodo!$C$39:$C$41,MATCH($K24,Metodo!$B$39:$B$41,0)),0)) | M24: =IF($L24="","",IF($L24>=Metodo!$C$43,"A",IF($L24>=Metodo!$C$44,"B","C"))) | N24: Nao contatado | Q24: Primeiro contato | T24: Tier 2 (varredura TomTom 2026-08-29, PR #185). Qualificacao: afiliado oficial.
A25: =IF($B25="","",ROW()-1) | B25: CrossFit Higienópolis | C25: São Paulo - Consolação | E25: +55 11 96336-6412 | K25: Grande SP | L25: =IF($B25="","",IF($F25="",Metodo!$C$30,IF(AND($F25>=80,$F25<=250),Metodo!$C$28,IF(OR(AND($F25>=40,$F25<=79),AND($F25>=251,$F25<=400)),Metodo!$C$29,Metodo!$C$30)))+IFERROR(INDEX(Metodo!$C$32:$C$35,MATCH($G25,Metodo!$B$32:$B$35,0)),0)+COUNTIF($H25:$J25,"Sim")*Metodo!$C$37+IFERROR(INDEX(Metodo!$C$39:$C$41,MATCH($K25,Metodo!$B$39:$B$41,0)),0)) | M25: =IF($L25="","",IF($L25>=Metodo!$C$43,"A",IF($L25>=Metodo!$C$44,"B","C"))) | N25: Nao contatado | Q25: Primeiro contato | T25: Tier 2 (varredura TomTom 2026-08-29, PR #185). Qualificacao: afiliado oficial.
A26: =IF($B26="","",ROW()-1) | B26: CrossFit Juntos | C26: São Paulo - Itaim Bibi | E26: +55 11 99947-5785 | K26: Grande SP | L26: =IF($B26="","",IF($F26="",Metodo!$C$30,IF(AND($F26>=80,$F26<=250),Metodo!$C$28,IF(OR(AND($F26>=40,$F26<=79),AND($F26>=251,$F26<=400)),Metodo!$C$29,Metodo!$C$30)))+IFERROR(INDEX(Metodo!$C$32:$C$35,MATCH($G26,Metodo!$B$32:$B$35,0)),0)+COUNTIF($H26:$J26,"Sim")*Metodo!$C$37+IFERROR(INDEX(Metodo!$C$39:$C$41,MATCH($K26,Metodo!$B$39:$B$41,0)),0)) | M26: =IF($L26="","",IF($L26>=Metodo!$C$43,"A",IF($L26>=Metodo!$C$44,"B","C"))) | N26: Nao contatado | Q26: Primeiro contato | T26: Tier 2 (varredura TomTom 2026-08-29, PR #185). Qualificacao: afiliado oficial.
A27: =IF($B27="","",ROW()-1) | B27: CrossFit Rutilo | C27: São Paulo - Lapa | E27: +55 11 94390-7851 | K27: Grande SP | L27: =IF($B27="","",IF($F27="",Metodo!$C$30,IF(AND($F27>=80,$F27<=250),Metodo!$C$28,IF(OR(AND($F27>=40,$F27<=79),AND($F27>=251,$F27<=400)),Metodo!$C$29,Metodo!$C$30)))+IFERROR(INDEX(Metodo!$C$32:$C$35,MATCH($G27,Metodo!$B$32:$B$35,0)),0)+COUNTIF($H27:$J27,"Sim")*Metodo!$C$37+IFERROR(INDEX(Metodo!$C$39:$C$41,MATCH($K27,Metodo!$B$39:$B$41,0)),0)) | M27: =IF($L27="","",IF($L27>=Metodo!$C$43,"A",IF($L27>=Metodo!$C$44,"B","C"))) | N27: Nao contatado | Q27: Primeiro contato | T27: Tier 2 (varredura TomTom 2026-08-29, PR #185). Qualificacao: afiliado oficial.
A28: =IF($B28="","",ROW()-1) | B28: CrossFit Saga | C28: São Paulo - Vila Mariana | E28: +55 11 97349-2008 | K28: Grande SP | L28: =IF($B28="","",IF($F28="",Metodo!$C$30,IF(AND($F28>=80,$F28<=250),Metodo!$C$28,IF(OR(AND($F28>=40,$F28<=79),AND($F28>=251,$F28<=400)),Metodo!$C$29,Metodo!$C$30)))+IFERROR(INDEX(Metodo!$C$32:$C$35,MATCH($G28,Metodo!$B$32:$B$35,0)),0)+COUNTIF($H28:$J28,"Sim")*Metodo!$C$37+IFERROR(INDEX(Metodo!$C$39:$C$41,MATCH($K28,Metodo!$B$39:$B$41,0)),0)) | M28: =IF($L28="","",IF($L28>=Metodo!$C$43,"A",IF($L28>=Metodo!$C$44,"B","C"))) | N28: Nao contatado | Q28: Primeiro contato | T28: Tier 2 (varredura TomTom 2026-08-29, PR #185). Qualificacao: afiliado oficial.
A29: =IF($B29="","",ROW()-1) | B29: CrossFit Saurus | C29: São Paulo - Vila Guilherme | E29: +55 11 98254-0787 | K29: Grande SP | L29: =IF($B29="","",IF($F29="",Metodo!$C$30,IF(AND($F29>=80,$F29<=250),Metodo!$C$28,IF(OR(AND($F29>=40,$F29<=79),AND($F29>=251,$F29<=400)),Metodo!$C$29,Metodo!$C$30)))+IFERROR(INDEX(Metodo!$C$32:$C$35,MATCH($G29,Metodo!$B$32:$B$35,0)),0)+COUNTIF($H29:$J29,"Sim")*Metodo!$C$37+IFERROR(INDEX(Metodo!$C$39:$C$41,MATCH($K29,Metodo!$B$39:$B$41,0)),0)) | M29: =IF($L29="","",IF($L29>=Metodo!$C$43,"A",IF($L29>=Metodo!$C$44,"B","C"))) | N29: Nao contatado | Q29: Primeiro contato | T29: Tier 2 (varredura TomTom 2026-08-29, PR #185). Qualificacao: afiliado oficial.
A30: =IF($B30="","",ROW()-1) | B30: CrossFit São Francisco | C30: São Paulo - Jaguaré | E30: +55 11 97306-6942 | K30: Grande SP | L30: =IF($B30="","",IF($F30="",Metodo!$C$30,IF(AND($F30>=80,$F30<=250),Metodo!$C$28,IF(OR(AND($F30>=40,$F30<=79),AND($F30>=251,$F30<=400)),Metodo!$C$29,Metodo!$C$30)))+IFERROR(INDEX(Metodo!$C$32:$C$35,MATCH($G30,Metodo!$B$32:$B$35,0)),0)+COUNTIF($H30:$J30,"Sim")*Metodo!$C$37+IFERROR(INDEX(Metodo!$C$39:$C$41,MATCH($K30,Metodo!$B$39:$B$41,0)),0)) | M30: =IF($L30="","",IF($L30>=Metodo!$C$43,"A",IF($L30>=Metodo!$C$44,"B","C"))) | N30: Nao contatado | Q30: Primeiro contato | T30: Tier 2 (varredura TomTom 2026-08-29, PR #185). Qualificacao: afiliado oficial.
... A54: =IF($B54="","",ROW()-1) | B54: Box Utinga Crossfit | C54: Santo André - Vila Metalúrgica | E54: +55 11 4997-3228 | K54: Grande SP | L54: =IF($B54="","",IF($F54="",Metodo!$C$30,IF(AND($F54>=80,$F54<=250),Metodo!$C$28,IF(OR(AND($F54>=40,$F54<=79),AND($F54>=251,$F54<=400)),Metodo!$C$29,Metodo!$C$30)))+IFERROR(INDEX(Metodo!$C$32:$C$35,MATCH($G54,Metodo!$B$32:$B$35,0)),0)+COUNTIF($H54:$J54,"Sim")*Metodo!$C$37+IFERROR(INDEX(Metodo!$C$39:$C$41,MATCH($K54,Metodo!$B$39:$B$41,0)),0)) | M54: =IF($L54="","",IF($L54>=Metodo!$C$43,"A",IF($L54>=Metodo!$C$44,"B","C"))) | N54: Nao contatado | Q54: Primeiro contato | T54: Tier 3 (varredura TomTom 2026-08-29, PR #185). Qualificacao: site próprio.
A55: =IF($B55="","",ROW()-1) | B55: Crossfit 198 | C55: Santo André - Bairro Jardim | K55: Grande SP | L55: =IF($B55="","",IF($F55="",Metodo!$C$30,IF(AND($F55>=80,$F55<=250),Metodo!$C$28,IF(OR(AND($F55>=40,$F55<=79),AND($F55>=251,$F55<=400)),Metodo!$C$29,Metodo!$C$30)))+IFERROR(INDEX(Metodo!$C$32:$C$35,MATCH($G55,Metodo!$B$32:$B$35,0)),0)+COUNTIF($H55:$J55,"Sim")*Metodo!$C$37+IFERROR(INDEX(Metodo!$C$39:$C$41,MATCH($K55,Metodo!$B$39:$B$41,0)),0)) | M55: =IF($L55="","",IF($L55>=Metodo!$C$43,"A",IF($L55>=Metodo!$C$44,"B","C"))) | N55: Nao contatado | Q55: Achar contato | T55: Tier 3 (varredura TomTom 2026-08-29, PR #185). Qualificacao: sem site.
A56: =IF($B56="","",ROW()-1) | B56: Crossfit Badak | C56: Santo André - Centro | E56: +55 11 4432-2332 | K56: Grande SP | L56: =IF($B56="","",IF($F56="",Metodo!$C$30,IF(AND($F56>=80,$F56<=250),Metodo!$C$28,IF(OR(AND($F56>=40,$F56<=79),AND($F56>=251,$F56<=400)),Metodo!$C$29,Metodo!$C$30)))+IFERROR(INDEX(Metodo!$C$32:$C$35,MATCH($G56,Metodo!$B$32:$B$35,0)),0)+COUNTIF($H56:$J56,"Sim")*Metodo!$C$37+IFERROR(INDEX(Metodo!$C$39:$C$41,MATCH($K56,Metodo!$B$39:$B$41,0)),0)) | M56: =IF($L56="","",IF($L56>=Metodo!$C$43,"A",IF($L56>=Metodo!$C$44,"B","C"))) | N56: Nao contatado | Q56: Primeiro contato | T56: Tier 3 (varredura TomTom 2026-08-29, PR #185). Qualificacao: site próprio.
A57: =IF($B57="","",ROW()-1) | B57: Juscelino Kubitschek Crossfit | C57: Santo André - Bairro Jardim | E57: +55 11 2896-0253 | K57: Grande SP | L57: =IF($B57="","",IF($F57="",Metodo!$C$30,IF(AND($F57>=80,$F57<=250),Metodo!$C$28,IF(OR(AND($F57>=40,$F57<=79),AND($F57>=251,$F57<=400)),Metodo!$C$29,Metodo!$C$30)))+IFERROR(INDEX(Metodo!$C$32:$C$35,MATCH($G57,Metodo!$B$32:$B$35,0)),0)+COUNTIF($H57:$J57,"Sim")*Metodo!$C$37+IFERROR(INDEX(Metodo!$C$39:$C$41,MATCH($K57,Metodo!$B$39:$B$41,0)),0)) | M57: =IF($L57="","",IF($L57>=Metodo!$C$43,"A",IF($L57>=Metodo!$C$44,"B","C"))) | N57: Nao contatado | Q57: Primeiro contato | T57: Tier 3 (varredura TomTom 2026-08-29, PR #185). Qualificacao: sem site.
A58: =IF($B58="","",ROW()-1) | B58: Cross Planalto | C58: São Bernardo do Campo - Independência | E58: +55 11 4509-9888 | K58: Grande SP | L58: =IF($B58="","",IF($F58="",Metodo!$C$30,IF(AND($F58>=80,$F58<=250),Metodo!$C$28,IF(OR(AND($F58>=40,$F58<=79),AND($F58>=251,$F58<=400)),Metodo!$C$29,Metodo!$C$30)))+IFERROR(INDEX(Metodo!$C$32:$C$35,MATCH($G58,Metodo!$B$32:$B$35,0)),0)+COUNTIF($H58:$J58,"Sim")*Metodo!$C$37+IFERROR(INDEX(Metodo!$C$39:$C$41,MATCH($K58,Metodo!$B$39:$B$41,0)),0)) | M58: =IF($L58="","",IF($L58>=Metodo!$C$43,"A",IF($L58>=Metodo!$C$44,"B","C"))) | N58: Nao contatado | Q58: Primeiro contato | T58: Tier 3 (varredura TomTom 2026-08-29, PR #185). Qualificacao: site próprio.
A59: =IF($B59="","",ROW()-1) | B59: CrossFit Range | C59: São Bernardo do Campo - Baeta Neves | K59: Grande SP | L59: =IF($B59="","",IF($F59="",Metodo!$C$30,IF(AND($F59>=80,$F59<=250),Metodo!$C$28,IF(OR(AND($F59>=40,$F59<=79),AND($F59>=251,$F59<=400)),Metodo!$C$29,Metodo!$C$30)))+IFERROR(INDEX(Metodo!$C$32:$C$35,MATCH($G59,Metodo!$B$32:$B$35,0)),0)+COUNTIF($H59:$J59,"Sim")*Metodo!$C$37+IFERROR(INDEX(Metodo!$C$39:$C$41,MATCH($K59,Metodo!$B$39:$B$41,0)),0)) | M59: =IF($L59="","",IF($L59>=Metodo!$C$43,"A",IF($L59>=Metodo!$C$44,"B","C"))) | N59: Nao contatado | Q59: Achar contato | T59: Tier 3 (varredura TomTom 2026-08-29, PR #185). Qualificacao: site próprio.
A60: =IF($B60="","",ROW()-1) | B60: CrossFit Titânio | C60: São Bernardo do Campo - Centro | E60: +55 11 3380-6506 | K60: Grande SP | L60: =IF($B60="","",IF($F60="",Metodo!$C$30,IF(AND($F60>=80,$F60<=250),Metodo!$C$28,IF(OR(AND($F60>=40,$F60<=79),AND($F60>=251,$F60<=400)),Metodo!$C$29,Metodo!$C$30)))+IFERROR(INDEX(Metodo!$C$32:$C$35,MATCH($G60,Metodo!$B$32:$B$35,0)),0)+COUNTIF($H60:$J60,"Sim")*Metodo!$C$37+IFERROR(INDEX(Metodo!$C$39:$C$41,MATCH($K60,Metodo!$B$39:$B$41,0)),0)) | M60: =IF($L60="","",IF($L60>=Metodo!$C$43,"A",IF($L60>=Metodo!$C$44,"B","C"))) | N60: Nao contatado | Q60: Primeiro contato | T60: Tier 3 (varredura TomTom 2026-08-29, PR #185). Qualificacao: site próprio.
A61: =IF($B61="","",ROW()-1) | B61: Crossfit Capitão | C61: São Bernardo do Campo - Casa | E61: +55 11 4509-5333 | K61: Grande SP | L61: =IF($B61="","",IF($F61="",Metodo!$C$30,IF(AND($F61>=80,$F61<=250),Metodo!$C$28,IF(OR(AND($F61>=40,$F61<=79),AND($F61>=251,$F61<=400)),Metodo!$C$29,Metodo!$C$30)))+IFERROR(INDEX(Metodo!$C$32:$C$35,MATCH($G61,Metodo!$B$32:$B$35,0)),0)+COUNTIF($H61:$J61,"Sim")*Metodo!$C$37+IFERROR(INDEX(Metodo!$C$39:$C$41,MATCH($K61,Metodo!$B$39:$B$41,0)),0)) | M61: =IF($L61="","",IF($L61>=Metodo!$C$43,"A",IF($L61>=Metodo!$C$44,"B","C"))) | N61: Nao contatado | Q61: Primeiro contato | T61: Tier 3 (varredura TomTom 2026-08-29, PR #185). Qualificacao: sem site.
A62: =IF($B62="","",ROW()-1) | B62: Crossfit Tamoko | C62: São Bernardo do Campo - Rudge Ramos | E62: +55 11 99664-7999 | K62: Grande SP | L62: =IF($B62="","",IF($F62="",Metodo!$C$30,IF(AND($F62>=80,$F62<=250),Metodo!$C$28,IF(OR(AND($F62>=40,$F62<=79),AND($F62>=251,$F62<=400)),Metodo!$C$29,Metodo!$C$30)))+IFERROR(INDEX(Metodo!$C$32:$C$35,MATCH($G62,Metodo!$B$32:$B$35,0)),0)+COUNTIF($H62:$J62,"Sim")*Metodo!$C$37+IFERROR(INDEX(Metodo!$C$39:$C$41,MATCH($K62,Metodo!$B$39:$B$41,0)),0)) | M62: =IF($L62="","",IF($L62>=Metodo!$C$43,"A",IF($L62>=Metodo!$C$44,"B","C"))) | N62: Nao contatado | Q62: Primeiro contato | T62: Tier 3 (varredura TomTom 2026-08-29, PR #185). Qualificacao: sem site.
A63: =IF($B63="","",ROW()-1) | B63: Crossfit Voraz | C63: São Bernardo do Campo - Centro | E63: +55 11 97698-1669 | K63: Grande SP | L63: =IF($B63="","",IF($F63="",Metodo!$C$30,IF(AND($F63>=80,$F63<=250),Metodo!$C$28,IF(OR(AND($F63>=40,$F63<=79),AND($F63>=251,$F63<=400)),Metodo!$C$29,Metodo!$C$30)))+IFERROR(INDEX(Metodo!$C$32:$C$35,MATCH($G63,Metodo!$B$32:$B$35,0)),0)+COUNTIF($H63:$J63,"Sim")*Metodo!$C$37+IFERROR(INDEX(Metodo!$C$39:$C$41,MATCH($K63,Metodo!$B$39:$B$41,0)),0)) | M63: =IF($L63="","",IF($L63>=Metodo!$C$43,"A",IF($L63>=Metodo!$C$44,"B","C"))) | N63: Nao contatado | Q63: Primeiro contato | T63: Tier 3 (varredura TomTom 2026-08-29, PR #185). Qualificacao: site próprio.
...

Sheet Objecoes
B2: Log de objecoes
B3: Registre TODA objecao, inclusive a que voce respondeu bem. Este log e o rascunho do playbook da Fase 2 e, mais tarde, o insumo do Growth Engine.
B5: Data | C5: Box | D5: Objecao (palavras dele) | E5: Categoria | F5: Resposta que dei | G5: Funcionou? | H5: Virou venda? | J5: Ranking de objecoes
J6: Categoria | L6: Vezes
J7: Preco | L7: =COUNTIF($E$6:$E$105,"Preco")
J8: PIX / recorrencia | L8: =COUNTIF($E$6:$E$105,"PIX / recorrencia")
J9: Ja uso concorrente | L9: =COUNTIF($E$6:$E$105,"Ja uso concorrente")
J10: Agora nao / sem tempo | L10: =COUNTIF($E$6:$E$105,"Agora nao / sem tempo")
J11: Confianca (fundador solo) | L11: =COUNTIF($E$6:$E$105,"Confianca (fundador solo)")
J12: Falta feature | L12: =COUNTIF($E$6:$E$105,"Falta feature")
J13: Precisa falar com socio | L13: =COUNTIF($E$6:$E$105,"Precisa falar com socio")
J14: Outro | L14: =COUNTIF($E$6:$E$105,"Outro")
J16: A objecao do topo desta lista e a proxima prioridade de produto.
